Workbook

Sheet 0A_総括
A1: JLPT N3 問題傾向分析 総括（2026-08-13 時点／資料5種）
A3: 公式102問・スピードマスター264問・パターン別徹底ドリル131問を実測し、さらに5冊のさくいん（語彙3冊・文型2冊・漢字1冊）でカバー率を数えた。
A4: 分析は「分類のメタ情報と統計値」のみ。公式の本文・スクリプト・設問文・選択肢の文言は一切収録していない。
A5: 正答は N3answer.pdf から確定。N1のときは正答表が無く自分で解いて作ったが、N3は公式の正答をそのまま使えた。
A7: ■ 分析した資料の量 | D7: 市販SM | F7: ドリル
A8: 科目 | B8: 公式問題集 | C8: 当サイト | D8: 市販SM | E8: おもな出典 | F8: ドリル
A9: 文字・語彙 | B9: 35 | C9: 3255 | D9: 42 | E9: N3V ／ 語彙SM模試1・2（正解なし）／ドリルp.7-54（未処理）／新完マ漢字さくいん442字 | F9: 索引451
A10: 文法 | B10: 23 | C10: 300 | D10: 69 | E10: N3G ／ 文法SM模試1〜3（正解なし）／ドリルp.131-178 | F10: 未処理
A11: 読解 | B11: 16 | C11: 101 | D11: 16 | E11: N3R ／ 読解SM模試（解答つき）／ドリルp.179-200 | F11: 19
A12: 聴解 | B12: 28 | C12: 182 | D12: 137 | E12: N3L＋N3script ／ 聴解SM 実戦練習81＋模試2回56 ／ドリルp.55-130 | F12: 112
A13: 合計 | B13: =SUM(B9:B12) -> 102 | C13: =SUM(C9:C12) -> 3838 | D13: =SUM(D9:D12) -> 264 | E13: ＋ 文法項目さくいん338／語彙さくいん1,879語／N3大問のねらい／N3answer（正答表） | F13: =SUM(F9:F12) -> 131
A14: ※ 受領済み・未処理：新完全マスター聴解スクリプト46p／同 読解・語彙・聴解の模試23p／パターン別ドリルの文字語彙48p・文法48p／短期マスター47p／日本語総まとめ聴解51p。いずれも既に決着した項目の4本目・5本目の裏づけにしかならないので後回し。
A15: # | B15: 対象 | C15: いまの状態 | D15: 目標 | E15: 根拠・メモ
A16: 1 | B16: 発話表現42問・即時応答50問の選択肢の数 | C16: 4つ | D16: 3つ | E16: ★3資料すべてで3つ。例外なし。音声の作り直しは不要。→ 発話表現42問は 2026-08-13 完了。即時応答50問が残り
A17: 2 | B17: 聴解4大問140問の台本の長さ | C17: 課題87／ポイント78／概要122／即時16字 | D17: 課題150〜247／ポイント176〜285字 | E17: ★3資料の数字はばらつくが、当サイトはどれよりも小さい。練習用ドリルと比べても6割・4割。音声140本
A18: 3 | B18: 聴解の発話数 | C18: 課題4.1／ポイント3.7回 | D18: 課題5.8〜8.4／ポイント5.9〜6.9回 | E18: ★3資料がそろう。公式だけだと幅1〜9回で◯に見えていた。2と一度に直す
A19: 4 | B19: 概要理解30問を独話に寄せすぎ | C19: 30問すべて独話 | D19: 6〜8問を会話に（独話7〜8割） | E19: ★41問中31問が独話。市販だけ会話が半分。第二陣で「半々」と書いたのをドリルで修正した
A20: 5 | B20: 選択肢を音声で読む（概要理解・発話表現・即時応答） | C20: 画面に出している | D20: 音声で読む | E20: ★発話表現の問題用紙は3資料ともイラストのみ。音声122本。2・3・4と一度に
A21: 6 | B21: ★語彙「本命」517語のカバー | C21: 169語が未カバー（67%） | D21: 9割以上 | E21: ★3冊のうち2冊以上が載せている語。14_カバー総覧 の末尾に169語の一覧がある。ここが作問の第一候補
A22: 7 | B22: 文型のカバー | C22: 2冊合併518項目中291項目が未カバー（44%） | D22: 7割以上 | E22: ★どちらの本から見ても4割台。文法300問は語彙3,255問に比べて手薄
A23: 8 | B23: 読解 短文20問の選択肢 | C23: 16.4字 | D23: 26.8〜32.4字 | E23: ★公式32.4・市販26.8。ドリル18.1は練習用で外れる。当サイトはドリルより短い
A24: 9 | B24: 場面の偏り（聴解182問） | C24: S02友人49／S07職場39で半数 | D24: 1場面20問以下 | E24: 未使用9場面：役所・銀行・引っ越し・イベント・留守電・ネット・学校事務・部活・スポーツ教室
A25: 10 | B25: 情報検索46問の資料と選択肢 | C25: 9種類の使い回し／選択肢6.3字 | D25: 資料を増やす／11〜35字 | E25: 3資料とも選択肢は11字以上。設問の不備2問も直す（90シート）
A26: 11 | B26: 聴解の肢の長短差 | C26: ポイント3.5／概要3.6／即時3.3字 | D26: ポイント4.3〜6.5／概要4.5〜6.4字 | E26: 3資料がそろっている。当サイトはそろえすぎ
A27: 12 | B27: 誤答型「本文にない情報(W15)」への寄りかかり | C27: 聴解160件・読解70件で最多 | D27: 半分以下に | E27: 誤答が「関係ない文」だと消去法で消しやすい
... A30: 15 | B30: 漢字のカバー（優先度は低い） | C30: 442字中37字が未出題（92%） | D30: ― | E30: 9割超なので後回し。未出題37字：厚糸億階各彼側簡黄君橋草誌紙初紹船総早則卒短池妻庭寺荷倍普副枚窓皆昔薬練渡
A31: ※ 第一陣で★2に置いた「発話表現の肢の長短差」は取り下げ（公式1.8字4問に対し市販3.4・ドリル3.6）。
A33: ■ 触らなくてよいもの（公式と市販の両方で「適正」と確認できた）
A34: ・読解の本文の長さ（短文236字／長文617字。公式230／653字、市販277／807字の幅の中）
A35: ・読解・文字語彙・文法の 最長肢／最短肢正解率（4部門とも公式・市販の幅の中）
A36: ・聴解の話者の組み立て（同じ話者が続けて話す問題ゼロ。公式も市販も0）
A37: ・課題理解の選択肢の長さ（9.8字。公式7.1・市販5.9の幅の中）
A38: ・即時応答の選択肢の長さと長短差（13.3字／3.3字。公式13.5／4.1、市販12.2／3.8）
A39: ・読解の肢の長短差（2.9字。公式1〜13字、市販1〜15字）
A40: ・発話表現の肢の長短差（4.2字。公式1.8字と市販3.4字が食い違うので追いかけない。市販の幅0〜11の中）
A41: ■ N1と作りが違うところ（N1のマスターをそのまま使えない点）
A42: ・文字・語彙に「表記」（ひらがな→漢字）がある。N1には無い
A43: ・聴解に「発話表現」（イラストを見て適切な発話を選ぶ）がある。N1には無い。→ 分類軸 U01〜U12 を新設した
... A72: rankを優先する。誤答を書き直すのは正常な作問であって、逃げではない。

Sheet 00_概要
A1: JLPT N3 問題傾向マスター
A2: 数字はすべて他シートを数える式です。10_聴解 と 20_読解 に行を足せば自動で増えます。
A4: ① 大問ごとの問題数
A5: 科目 | B5: 大問 | C5: 現在 | D5: 目標 | E5: 不足 | F5: 充足率
A6: 聴解 | B6: 課題理解 | C6: =COUNTIF(10_聴解!$C:$C,$B6) -> 30 | D6: 60 | E6: =MAX(0,$D6-$C6) -> 30 | F6: =IFERROR($C6/$D6,0) -> 0.5
A7: 聴解 | B7: ポイント理解 | C7: =COUNTIF(10_聴解!$C:$C,$B7) -> 30 | D7: 60 | E7: =MAX(0,$D7-$C7) -> 30 | F7: =IFERROR($C7/$D7,0) -> 0.5
A8: 聴解 | B8: 概要理解 | C8: =COUNTIF(10_聴解!$C:$C,$B8) -> 30 | D8: 60 | E8: =MAX(0,$D8-$C8) -> 30 | F8: =IFERROR($C8/$D8,0) -> 0.5
A9: 聴解 | B9: 発話表現 | C9: =COUNTIF(10_聴解!$C:$C,$B9) -> 42 | D9: 60 | E9: =MAX(0,$D9-$C9) -> 18 | F9: =IFERROR($C9/$D9,0) -> 0.7
A10: 聴解 | B10: 即時応答 | C10: =COUNTIF(10_聴解!$C:$C,$B10) -> 50 | D10: 60 | E10: =MAX(0,$D10-$C10) -> 10 | F10: =IFERROR($C10/$D10,0) -> 0.83333333
A11: 読解 | B11: 内容理解（短文） | C11: =COUNTIF(20_読解!$C:$C,$B11) -> 20 | D11: 40 | E11: =MAX(0,$D11-$C11) -> 20 | F11: =IFERROR($C11/$D11,0) -> 0.5
A12: 読解 | B12: 内容理解（中文） | C12: =COUNTIF(20_読解!$C:$C,$B12) -> 15 | D12: 30 | E12: =MAX(0,$D12-$C12) -> 15 | F12: =IFERROR($C12/$D12,0) -> 0.5
A13: 読解 | B13: 内容理解（長文） | C13: =COUNTIF(20_読解!$C:$C,$B13) -> 20 | D13: 40 | E13: =MAX(0,$D13-$C13) -> 20 | F13: =IFERROR($C13/$D13,0) -> 0.5
A14: 読解 | B14: 情報検索 | C14: =COUNTIF(20_読解!$C:$C,$B14) -> 46 | D14: 40 | E14: =MAX(0,$D14-$C14) -> 0 | F14: =IFERROR($C14/$D14,0) -> 1.15
A15: 合計 | C15: =SUM($C6:$C14) -> 283 | D15: =SUM($D6:$D14) -> 450 | E15: =SUM($E6:$E14) -> 173
A17: ② 場面の使用状況（聴解） | H17: ③ 展開型の使用状況（聴解＋読解）
A18: コード | B18: 場面 | C18: 使用数 | H18: コード | I18: 展開型 | J18: 使用数
A19: S01 | B19: 家庭・家族の会話 | C19: =COUNTIF(10_聴解!$D:$D,$A19) -> 10 | H19: D01 | I19: 条件つき先行：Aの前にBをする | J19: =COUNTIF(10_聴解!$J:$J,$H19)+COUNTIF(20_読解!$H:$H,$H19) -> 28
A20: S02 | B20: 友人・知人どうし | C20: =COUNTIF(10_聴解!$D:$D,$A20) -> 49 | H20: D02 | I20: 予定の変更：都合が悪くなって順序が変わる | J20: =COUNTIF(10_聴解!$J:$J,$H20)+COUNTIF(20_読解!$H:$H,$H20) -> 3
A21: S03 | B21: 学校・教室／授業 | C21: =COUNTIF(10_聴解!$D:$D,$A21) -> 15 | H21: D03 | I21: いったん決めて覆す | J21: =COUNTIF(10_聴解!$J:$J,$H21)+COUNTIF(20_読解!$H:$H,$H21) -> 3
A22: S04 | B22: 学校・事務／手続き | C22: =COUNTIF(10_聴解!$D:$D,$A22) -> 0 | H22: D04 | I22: 分担：どちらがやるか | J22: =COUNTIF(10_聴解!$J:$J,$H22)+COUNTIF(20_読解!$H:$H,$H22) -> 1
A23: S05 | B23: 学校・部活／サークル | C23: =COUNTIF(10_聴解!$D:$D,$A23) -> 0 | H23: D05 | I23: 表面の理由と本当の理由 | J23: =COUNTIF(10_聴解!$J:$J,$H23)+COUNTIF(20_読解!$H:$H,$H23) -> 8
A24: S06 | B24: 大学・研究室／ゼミ | C24: =COUNTIF(10_聴解!$D:$D,$A24) -> 2 | H24: D06 | I24: 条件の突き合わせ：条件に合う一つを選ぶ | J24: =COUNTIF(10_聴解!$J:$J,$H24)+COUNTIF(20_読解!$H:$H,$H24) -> 49
A25: S07 | B25: 職場・同僚どうし | C25: =COUNTIF(10_聴解!$D:$D,$A25) -> 39 | H25: D07 | I25: 前置きのあと本題 | J25: =COUNTIF(10_聴解!$J:$J,$H25)+COUNTIF(20_読解!$H:$H,$H25) -> 11
A26: S08 | B26: 職場・上司と部下 | C26: =COUNTIF(10_聴解!$D:$D,$A26) -> 3 | H26: D08 | I26: 対比：前と今／自分と他人 | J26: =COUNTIF(10_聴解!$J:$J,$H26)+COUNTIF(20_読解!$H:$H,$H26) -> 28
A27: S09 | B27: 職場・電話／来客対応 | C27: =COUNTIF(10_聴解!$D:$D,$A27) -> 5 | H27: D09 | I27: 譲歩からの転換：〜だけど〜 | J27: =COUNTIF(10_聴解!$J:$J,$H27)+COUNTIF(20_読解!$H:$H,$H27) -> 21
A28: S10 | B28: アルバイト先 | C28: =COUNTIF(10_聴解!$D:$D,$A28) -> 4 | H28: D10 | I28: 具体例から結論 | J28: =COUNTIF(10_聴解!$J:$J,$H28)+COUNTIF(20_読解!$H:$H,$H28) -> 22
A29: S11 | B29: 店・買い物／商品選び | C29: =COUNTIF(10_聴解!$D:$D,$A29) -> 9 | H29: D11 | I29: 即応：短い発話への応答 | J29: =COUNTIF(10_聴解!$J:$J,$H29)+COUNTIF(20_読解!$H:$H,$H29) -> 50
A30: S12 | B30: 店・注文／予約 | C30: =COUNTIF(10_聴解!$D:$D,$A30) -> 1 | H30: D12 | I30: 場面から適切な一言（発話表現） | J30: =COUNTIF(10_聴解!$J:$J,$H30)+COUNTIF(20_読解!$H:$H,$H30) -> 42
... A32: S14 | B32: レストラン・飲食店 | C32: =COUNTIF(10_聴解!$D:$D,$A32) -> 8 | H32: D14 | I32: 説明のあとに注意点 | J32: =COUNTIF(10_聴解!$J:$J,$H32)+COUNTIF(20_読解!$H:$H,$H32) -> 17
A33: S15 | B33: 病院・薬局 | C33: =COUNTIF(10_聴解!$D:$D,$A33) -> 3
A34: S16 | B34: 駅・空港・交通機関 | C34: =COUNTIF(10_聴解!$D:$D,$A34) -> 8
A35: S17 | B35: 役所・窓口 | C35: =COUNTIF(10_聴解!$D:$D,$A35) -> 0
A36: S18 | B36: 銀行・郵便局 | C36: =COUNTIF(10_聴解!$D:$D,$A36) -> 0
A37: S19 | B37: 住まい・引っ越し／不動産 | C37: =COUNTIF(10_聴解!$D:$D,$A37) -> 0
A38: S20 | B38: 図書館・公共施設 | C38: =COUNTIF(10_聴解!$D:$D,$A38) -> 4
A39: S21 | B39: 旅行・観光・ホテル | C39: =COUNTIF(10_聴解!$D:$D,$A39) -> 3
A40: S22 | B40: スポーツ・習い事・教室 | C40: =COUNTIF(10_聴解!$D:$D,$A40) -> 0
A41: S23 | B41: 地域・近所づきあい | C41: =COUNTIF(10_聴解!$D:$D,$A41) -> 1
A42: S24 | B42: イベント・お祭り | C42: =COUNTIF(10_聴解!$D:$D,$A42) -> 0
A43: S25 | B43: 放送・ラジオ／テレビ | C43: =COUNTIF(10_聴解!$D:$D,$A43) -> 16
...

Sheet 01_分類マスタ
A1: JLPT N3 問題傾向 分類マスタ
A2: ここにあるコードだけを各シートで使う。新しい分類が要るときは、まずこのシートに追加してから使う。
A3: N1のマスタから、N3の出題（日常生活・学校・買い物が中心）に合わせて作り直したもの。U（発話表現の型）はN3固有。
A5: 区分 | B5: コード | C5: 名称
A6: 場面 | B6: S01 | C6: 家庭・家族の会話
A7: 場面 | B7: S02 | C7: 友人・知人どうし
A8: 場面 | B8: S03 | C8: 学校・教室／授業
A9: 場面 | B9: S04 | C9: 学校・事務／手続き
A10: 場面 | B10: S05 | C10: 学校・部活／サークル
A11: 場面 | B11: S06 | C11: 大学・研究室／ゼミ
A12: 場面 | B12: S07 | C12: 職場・同僚どうし
A13: 場面 | B13: S08 | C13: 職場・上司と部下
A14: 場面 | B14: S09 | C14: 職場・電話／来客対応
A15: 場面 | B15: S10 | C15: アルバイト先
A16: 場面 | B16: S11 | C16: 店・買い物／商品選び
... A171: 発話表現の型（N3固有） | B171: U12 | C171: 気づかう・心配する

Sheet 07_公式問題集ベンチマーク
A1: N3 公式問題集ベンチマーク（2026-08-12 実測）
A2: 「作問の条件」は必ずこの表から取る。当サイトの既存データの min/max を条件にしない（いまのズレをそのまま固定してしまう）。
A4: 科目 | B4: 大問 | C4: 項目 | D4: 公式の平均 | E4: 許容の下 | F4: 許容の上 | G4: 当サイト | H4: 判定 | I4: メモ
A5: 聴解 | B5: 課題理解 | C5: 発話数 | D5: 6.8 | E5: 1 | F5: 9 | G5: 4.1 | H5: ◯
A6: 聴解 | B6: 課題理解 | C6: 台本字数 | D6: 247.2 | E6: 187 | F6: 330 | G6: 87.2 | H6: ×
A7: 聴解 | B7: 課題理解 | C7: 選択肢字数 | D7: 7.1 | E7: 2 | F7: 12 | G7: 9.8 | H7: ◯
A8: 聴解 | B8: 課題理解 | C8: 肢の長短差 | D8: 2.7 | E8: 0 | F8: 6 | G8: 3 | H8: ◯
A9: 聴解 | B9: 課題理解 | C9: 選択肢の数 | D9: 4 | E9: 4 | F9: 4 | G9: 4 | H9: ◯
A10: 聴解 | B10: 課題理解 | C10: 選択肢を音声で読む | D10: いいえ | G10: いいえ（画面に出している） | H10: ◯
A11: 聴解 | B11: 課題理解 | C11: 場面＋設問の字数 | D11: 37.5 | E11: 27 | F11: 44
A12: 聴解 | B12: ポイント理解 | C12: 発話数 | D12: 6.2 | E12: 1 | F12: 10 | G12: 3.7 | H12: ◯
A13: 聴解 | B13: ポイント理解 | C13: 台本字数 | D13: 285 | E13: 163 | F13: 384 | G13: 77.8 | H13: ×
A14: 聴解 | B14: ポイント理解 | C14: 選択肢字数 | D14: 12.8 | E14: 6 | F14: 19 | G14: 11.7 | H14: ◯
A15: 聴解 | B15: ポイント理解 | C15: 肢の長短差 | D15: 6.5 | E15: 4 | F15: 8 | G15: 3.5 | H15: ×
A16: 聴解 | B16: ポイント理解 | C16: 選択肢の数 | D16: 4 | E16: 4 | F16: 4 | G16: 4 | H16: ◯
A17: 聴解 | B17: ポイント理解 | C17: 選択肢を音声で読む | D17: いいえ | G17: いいえ（画面に出している） | H17: ◯
A18: 聴解 | B18: ポイント理解 | C18: 場面＋設問の字数 | D18: 43.3 | E18: 37 | F18: 57
A19: 聴解 | B19: 概要理解 | C19: 発話数 | D19: 1 | E19: 1 | F19: 1 | G19: 1 | H19: ◯
A20: 聴解 | B20: 概要理解 | C20: 台本字数 | D20: 212 | E20: 191 | F20: 242 | G20: 122.2 | H20: ×
A21: 聴解 | B21: 概要理解 | C21: 選択肢字数 | D21: 11.8 | E21: 8 | F21: 18 | G21: 13.7 | H21: ◯
A22: 聴解 | B22: 概要理解 | C22: 肢の長短差 | D22: 4.7 | E22: 3 | F22: 7 | G22: 3.6 | H22: ◯
A23: 聴解 | B23: 概要理解 | C23: 選択肢の数 | D23: 4 | E23: 4 | F23: 4 | G23: 4 | H23: ◯
A24: 聴解 | B24: 概要理解 | C24: 選択肢を音声で読む | D24: はい | G24: いいえ（画面に出している） | H24: ×
A25: 聴解 | B25: 概要理解 | C25: 場面＋設問の字数 | D25: 17.7 | E25: 17 | F25: 18
A26: 聴解 | B26: 発話表現 | C26: 発話数 | D26: 0 | E26: 0 | F26: 0 | G26: 0 | H26: ◯
A27: 聴解 | B27: 発話表現 | C27: 台本字数 | D27: 0 | E27: 0 | F27: 0 | G27: 0 | H27: ◯
A28: 聴解 | B28: 発話表現 | C28: 選択肢字数 | D28: 12.5 | E28: 8 | F28: 16 | G28: 14.6 | H28: ◯
A29: 聴解 | B29: 発話表現 | C29: 肢の長短差 | D29: 1.8 | E29: 1 | F29: 3 | G29: 4.2 | H29: ×
A30: 聴解 | B30: 発話表現 | C30: 選択肢の数 | D30: 3 | E30: 3 | F30: 3 | G30: 4 | H30: × | I30: 公式は3つ
A31: 聴解 | B31: 発話表現 | C31: 選択肢を音声で読む | D31: はい | G31: いいえ（画面に出している） | H31: ×
A32: 聴解 | B32: 発話表現 | C32: 場面＋設問の字数 | D32: 34 | E32: 25 | F32: 44
A33: 聴解 | B33: 即時応答 | C33: 発話数 | D33: 1 | E33: 1 | F33: 1 | G33: 1 | H33: ◯
A34: 聴解 | B34: 即時応答 | C34: 台本字数 | D34: 27.2 | E34: 21 | F34: 33 | G34: 15.5 | H34: ×
A35: 聴解 | B35: 即時応答 | C35: 選択肢字数 | D35: 13.5 | E35: 7 | F35: 21 | G35: 13.3 | H35: ◯
A36: 聴解 | B36: 即時応答 | C36: 肢の長短差 | D36: 4.1 | E36: 2 | F36: 9 | G36: 3.3 | H36: ◯
A37: 聴解 | B37: 即時応答 | C37: 選択肢の数 | D37: 3 | E37: 3 | F37: 3 | G37: 4 | H37: × | I37: 公式は3つ
A38: 聴解 | B38: 即時応答 | C38: 選択肢を音声で読む | D38: はい | G38: いいえ（画面に出している） | H38: ×
A39: 聴解 | B39: 即時応答 | C39: 場面＋設問の字数 | D39: 0 | E39: 0 | F39: 0
A41: 読解 | B41: 内容理解（短文） | C41: 本文字数 | D41: 230.3 | E41: 211 | F41: 251 | G41: 236.1 | H41: ◯
A42: 読解 | B42: 内容理解（短文） | C42: 選択肢字数 | D42: 32.4 | E42: 19 | F42: 38 | G42: 16.4 | H42: ×
...

Sheet 03_資料3本の突き合わせ
A1: 公式・市販スピードマスター・パターン別徹底ドリル の3本を並べる
A2: 公式102問／市販SM264問／ドリル(聴解112・読解19)。★判定は「幅の中か」ではなく「3資料の平均の幅の中か」で見る。
A3: 幅（最小〜最大）で見ると、独話が1問混ざるだけで下限が1になり、半分しかなくても◯になってしまう。△は、ねらう平均の幅からのはみ出しが1割以内＝ほぼ誤差。
A5: 科目 | B5: 大問 | C5: 項目 | D5: 公式 | E5: 市販SM | F5: ドリル | G5: 当サイト | H5: ねらう平均 | I5: 判定 | J5: 3資料の一致
A6: 聴解 | B6: 課題理解 | C6: 発話数 | D6: 6.8（1〜9） | E6: 8.4（3〜13） | F6: 5.8（2〜12） | G6: 4.1 | H6: 7.0（5.8〜8.4） | I6: × | J6: そろっている
A7: 聴解 | B7: 課題理解 | C7: 台本字数 | D7: 247.2（187〜330） | E7: 223.7（123〜312） | F7: 149.6（74〜391） | G7: 87.2 | H7: 206.8（149.6〜247.2） | I7: × | J7: ★ばらばら（追いかけない）
A8: 聴解 | B8: 課題理解 | C8: 選択肢字数 | D8: 7.1（2〜12） | E8: 5.9（2〜12） | F8: 9.0（2〜20） | G8: 9.8 | H8: 7.3（5.9〜9.0） | I8: × | J8: そろっている
A9: 聴解 | B9: 課題理解 | C9: 肢の長短差 | D9: 2.7（0〜6） | E9: 2.9（0〜8） | F9: 2.6（0〜7） | G9: 3 | H9: 2.7（2.6〜2.9） | I9: △ | J9: そろっている
A10: 聴解 | B10: ポイント理解 | C10: 発話数 | D10: 6.2（1〜10） | E10: 6.9（1〜14） | F10: 5.9（1〜9） | G10: 3.7 | H10: 6.3（5.9〜6.9） | I10: × | J10: そろっている
A11: 聴解 | B11: ポイント理解 | C11: 台本字数 | D11: 285（163〜384） | E11: 230.4（121〜463） | F11: 175.9（124〜235） | G11: 77.8 | H11: 230.4（175.9〜285） | I11: × | J11: ★ばらばら（追いかけない）
A12: 聴解 | B12: ポイント理解 | C12: 選択肢字数 | D12: 12.8（6〜19） | E12: 8.1（2〜27） | F12: 12.2（2〜30） | G12: 11.7 | H12: 11.0（8.1〜12.8） | I12: ◯ | J12: そろっている
A13: 聴解 | B13: ポイント理解 | C13: 肢の長短差 | D13: 6.5（4〜8） | E13: 4.3（0〜15） | F13: 4.6（0〜10） | G13: 3.5 | H13: 5.1（4.3〜6.5） | I13: × | J13: そろっている
A14: 聴解 | B14: 概要理解 | C14: 発話数 | D14: 1（1〜1） | E14: 10.0（1〜15） | F14: 1（1〜1） | G14: 1 | H14: 1.0（1〜1） | I14: ◯ | J14: ★市販だけ外れる（多数決）
A15: 聴解 | B15: 概要理解 | C15: 台本字数 | D15: 212（191〜242） | E15: 269.6（161〜366） | F15: 183.1（96〜307） | G15: 122.2 | H15: 226.4（183.1〜269.6） | I15: × | J15: ★公式だけ外れる（多数決）
A16: 聴解 | B16: 概要理解 | C16: 選択肢字数 | D16: 11.8（8〜18） | E16: 12.1（1〜21） | F16: 14.2（2〜32） | G16: 13.7 | H16: 12.7（11.8〜14.2） | I16: ◯ | J16: そろっている
A17: 聴解 | B17: 概要理解 | C17: 肢の長短差 | D17: 4.7（3〜7） | E17: 4.5（2〜10） | F17: 6.4（1〜11） | G17: 3.6 | H17: 5.2（4.5〜6.4） | I17: × | J17: そろっている
... A37: 読解 | B37: 情報検索 | C37: 肢の長短差 | D37: 5（2〜8） | E37: 9.5（4〜15） | F37: 5（2〜9） | G37: 2.4 | H37: 5.0（5〜5） | I37: × | J37: ★市販だけ外れる（多数決）
A39: ― 3資料でそろって確かめられたこと ―
A40: ★選択肢の数：発話表現も即時応答も 3つ。公式・市販・ドリルの3資料すべてで一致、例外なし。当サイトは4つ。
A41: ★概要理解の話者：41問中31問（76%）が一人語り。公式3問・ドリル16問はすべて独話、市販SMだけ22問中10問が会話。
A42: 公式の「例」も女性2人の会話なので、会話がだめなわけではない。独話7〜8割・会話2〜3割が目安。
A43: 当サイトは30問すべて独話なので、6〜8問を会話にする。（第二陣の時点で「半々」と書いたのはドリルを入れて修正した）
A44: ★台本の長さ：3資料で 課題理解247/224/150字、ポイント理解285/230/176字。数字はばらつくが、
A45: 当サイトの87/78字は3つのどれよりも小さい。ドリル（練習用でいちばん短い）と比べても6割・4割しかない。
A46: ★発話数：課題理解6.8/8.4/5.8回、ポイント理解6.2/6.9/5.9回で3資料がそろう。当サイトの4.1/3.7回は3つのどれより少ない。
A47: ★読解 短文の選択肢：公式32.4・市販26.8に対しドリルは18.1字で外れる。ドリルは練習用で肢が短い。
A48: 多数決で「公式＋市販」を採り、ねらう平均は26.8〜32.4字。当サイトの16.4字はドリルより短い。

Sheet 14_カバー総覧
A1: 語彙・文型・漢字のカバー総覧（教材5冊のさくいん）
A2: 当サイトの文字語彙3,255問・文法300問・漢字読み1,854問の中に、その語／文型／漢字が出てくるかを機械で数えた。「（ ）」の中は入れた形・抜いた形の両方で照合している。
A4: リスト | B4: 総数 | C4: カバー | D4: 未カバー | E4: 率 | F4: メモ
A5: 語彙 スピードマスター | B5: 1879 | C5: 833 | D5: 1045 | E5: 44.4
A6: 語彙 新完全マスター | B6: 1023 | C6: 720 | D6: 239 | E6: 75.1 | F6: ★3冊で最も埋まっている。当サイトはこの本に近い語彙で作られている
A7: 語彙 日本語総まとめ | B7: 1189 | C7: 573 | D7: 578 | E7: 49.8
A8: 語彙 3冊の合併 | B8: 3693 | C8: 1869 | D8: 1735 | E8: 51.9 | F8: 重複を除いた延べ
A9: ★語彙 2冊以上に載る語 | B9: 517 | C9: 348 | D9: 169 | E9: 67.3 | F9: ★ここが本命。3冊のうち2冊以上が載せている＝N3で外せない語
A11: 文型 スピードマスター | B11: 338 | C11: 151 | D11: 186 | E11: 44.8
A12: 文型 日本語総まとめ | B12: 244 | C12: 110 | D12: 131 | E12: 45.6
A13: 文型 2冊の合併 | B13: 518 | C13: 224 | D13: 291 | E13: 43.5 | F13: ★どちらの本から見ても4割台。文法300問では足りていない
A15: 漢字 新完全マスター | B15: 442 | C15: 405 | D15: 37 | E15: 91.6 | F15: ★ここだけ9割超。漢字は足りている
A17: ■ 読み方
A18: ・語彙は本によってカバー率が44〜75%とばらつく。当サイトの語彙は「新完全マスター」に近い作りになっている。
A19: ・そこで、3冊のうち2冊以上が載せている517語を「本命」とした。ここが67.3%で、未カバーは169語。
A20: この169語から作れば、どの本を使っている学習者にも効く。
A21: ・文型は2冊とも4割台で、どちらから見ても足りない。文法300問は語彙3,255問に比べて手薄。
A22: ・漢字だけは91.6%。442字中37字が未出題で、ここは優先度が低い。
A24: ■ ★未カバーの「本命」語（作問の候補。169語）
A25: ミスする マスク ゆれる いきなり わくわくする サイト プラスする アドバイスする
A26: キッチン ゼミ ノートパソコン のんびりする ブログ イメージする おしゃれな ふきん
A27: いっぺんに パジャマ セール プリント くだらない マイナスする パスワード ぎりぎり
A28: いき行き シンプルな デザインする サボる スピーチする おかず わがままな あやしい
A29: サンダル アマチュア ななめ カーペット ぴかぴか ちりとり おすすめ ゆるい
... A46: つまみ

Sheet 11_文型索引338カバー
A1: N3文法スピードマスター 文法項目さくいん 338項目のカバー状況
A2: 当サイトの文法300問の中に、その文型が出てくるかを機械で数えた。「（ ）」の中は入れた形・抜いた形の両方、「/」で並ぶものは片方ずつで照合している。
A3: カバー 151／未カバー 186 ＝ 44.8% ★未カバーが作問の候補
A5: 文型 | B5: カバー | C5: メモ
A6: (…のは)〜からだ | B6: ◯
A7: (どんなに)〜ことか | B7: ◯
A8: 〜(く)なる | B8: ◯
A9: 〜(さ)せられる | B9: ◯
A10: 〜(さ)せる | B10: ◯
A11: 〜(た)ところ | B11: ◯
A12: 〜(た)ばかりだ | B12: ◯
A13: 〜(て)ならない | B13: ◯
A14: 〜(という)ことだ | B14: ◯
A15: 〜(に)おいて | B15: ◯
A16: 〜(に)したがって | B16: ◯
A17: 〜(に)ついて | B17: ◯
... A342: 除き | B342: ×

Sheet 12_語彙索引1879カバー
A1: N3語彙スピードマスター 語彙さくいん 1,879語のカバー状況
A2: 当サイトの文字・語彙3,255問の中に、その語が出てくるかを機械で数えた。
A3: カバー 833／未カバー 1045 ＝ 44.4% ★未カバーが作問の候補
A5: 語 | B5: カバー | C5: メモ
A6: 〜あう（合う） | B6: ◯
A7: 〜あがる | B7: ◯
A8: 〜あけ（明け） | B8: ◯
A9: 〜あげる | B9: ◯
A10: 〜いか | B10: ◯
A11: 〜いき（行き） | B11: ◯
A12: 〜いじょう | B12: ◯
A13: 〜いない | B13: ◯
A14: 〜いん（員） | B14: ◯
A15: 〜がい（街） | B15: ◯
A16: 〜がえる | B16: ◯
A17: 〜がわ（側） | B17: ◯
... A1883: ワンルーム | B1883: ×

Sheet 13_漢字442字カバー
A1: 新完全マスターN3 漢字さくいん 442字＋熟字訓9語 のカバー状況
A2: 当サイトの漢字読み1,854問・表記343問の「出題語」にその漢字が使われているかを機械で数えた。
A3: カバー 405／未カバー 37 ＝ 91.6% ★文型45%・語彙44%より、漢字はよく埋まっている
A5: 漢字 | B5: 読み | C5: カバー | D5: メモ
A6: 愛 | B6: アイ | C6: ◯
A7: 相 | B7: あい・ショウ・ソウ | C7: ◯
A8: 預 | B8: あずかる・あずける・ヨ | C8: ◯
A9: 遊 | B9: あそぶ・ユウ | C9: ◯
A10: 暖 | B10: あたたかい・あたたまる・あたためる | C10: ◯
A11: 温 | B11: あたたかい・あたたまる・あたためる・オン | C11: ◯
A12: 辺 | B12: あたり | C12: ◯
A13: 当 | B13: あたる・あてる・トウ | C13: ◯
A14: 厚 | B14: あつい | C14: ×
A15: 熱 | B15: あつい・ネツ | C15: ◯
A16: 油 | B16: あぶら・ユ | C16: ◯
A17: 現 | B17: あらわす・あらわれる・ゲン | C17: ◯
... A447: 割 | B447: わり・わる・われる | C447: ◯
A448: 笑顔 | B448: えがお | C448: ◯ | D448: 熟字訓（1字に分けられない読み）
A449: 昨日 | B449: きのう | C449: × | D449: 熟字訓（1字に分けられない読み）
A450: 果物 | B450: くだもの | C450: ◯ | D450: 熟字訓（1字に分けられない読み）
A451: 景色 | B451: けしき | C451: ◯ | D451: 熟字訓（1字に分けられない読み）
A452: 手伝う | B452: てつだう | C452: ◯ | D452: 熟字訓（1字に分けられない読み）
A453: 友達 | B453: ともだち | C453: × | D453: 熟字訓（1字に分けられない読み）
A454: 二十歳 | B454: はたち | C454: × | D454: 熟字訓（1字に分けられない読み）
A455: 真っ赤 | B455: まっか | C455: ◯ | D455: 熟字訓（1字に分けられない読み）
A456: 真っ青 | B456: まっさお | C456: × | D456: 熟字訓（1字に分けられない読み）

Sheet 10_聴解
A1: ID | B1: 級 | C1: 大問 | D1: 場面 | E1: 場面名 | F1: 話題 | G1: 話題名 | H1: 機能 | I1: 機能名 | J1: 展開型 | K1: 展開型名 | L1: 話者関係 | M1: 話者関係名 | N1: 誤答型 | O1: 発話表現の型 | P1: 発話表現の型名 | Q1: 場面（音声の1文目） | R1: 台本字数 | S1: 発話数 | T1: 話者数 | U1: 選択肢数 | V1: 正解
A2: L001 | B2: N3 | C2: 課題理解 | D2: S07 | E2: 職場・同僚どうし | F2: T22 | G2: 仕事のやり方・段取り | H2: F01 | I2: 依頼する／依頼を受ける | J2: D01 | K2: 条件つき先行：Aの前にBをする | L2: R06 | M2: 同僚どうし | N2: W01／W15／W15 | Q2: 会社で、女の人と男の人が話しています。 | R2: 105 | S2: 4 | T2: 2 | U2: 4 | V2: 部長に資料を見せる
A3: L002 | B3: N3 | C3: 課題理解 | D3: S01 | E3: 家庭・家族の会話 | F3: T07 | G3: 住まい・部屋 | H3: F01 | I3: 依頼する／依頼を受ける | J3: D04 | K3: 分担：どちらがやるか | L3: R01 | M3: 家族 | N3: W03／W15／W02 | Q3: 電話で、妻と夫が話しています。 | R3: 118 | S3: 5 | T3: 2 | U3: 4 | V3: 洗濯物を取り込む
A4: L003 | B4: N3 | C4: 課題理解 | D4: S03 | E4: 学校・教室／授業 | F4: T08 | G4: 学校生活・勉強 | H4: F07 | I4: 助言する／指示する | J4: D06 | K4: 条件の突き合わせ：条件に合う一つを選ぶ | L4: R03 | M4: 先生と学生 | N4: W03／W03／W15 | Q4: 大学で、先生と学生が話しています。 | R4: 127 | S4: 4 | T4: 2 | U4: 4 | V4: 今日中にメールでレポートを送る
A5: L004 | B5: N3 | C5: ポイント理解 | D5: S02 | E5: 友人・知人どうし | F5: T04 | G5: 健康・体調・病気 | H5: F16 | I5: 説明する | J5: D05 | K5: 表面の理由と本当の理由 | L5: R02 | M5: 友人どうし | N5: W04／W08／W15 | Q5: 男の人と女の人が話しています。 | R5: 114 | S5: 6 | T5: 2 | U5: 4 | V5: 頭が痛くて病院に行っていたから
A6: L005 | B6: N3 | C6: ポイント理解 | D6: S13 | E6: 店・修理／サービス | F6: T02 | G6: 買い物・値段 | H6: F17 | I6: 比べる／選ぶ | J6: D03 | K6: いったん決めて覆す | L6: R07 | M6: 店員と客 | N6: W09／W15／W15 | Q6: クリーニング店で、女の人と店員が話しています。 | R6: 125 | S6: 5 | T6: 2 | U6: 4 | V6: 料金が３００円高くなるから
A7: L006 | B7: N3 | C7: ポイント理解 | D7: S02 | E7: 友人・知人どうし | F7: T11 | G7: 旅行・観光 | H7: F16 | I7: 説明する | J7: D09 | K7: 譲歩からの転換：〜だけど〜 | L7: R02 | M7: 友人どうし | N7: W15／W13／W15 | Q7: 男の人と女の人が、旅行について話しています。 | R7: 112 | S7: 5 | T7: 2 | U7: 4 | V7: 途中の町に寄って景色を楽しみたいから
A8: L007 | B8: N3 | C8: 概要理解 | D8: S25 | E8: 放送・ラジオ／テレビ | F8: T10 | G8: 趣味・スポーツ | H8: F19 | I8: 感想・気持ちを述べる | J8: D08 | K8: 対比：前と今／自分と他人 | L8: R10 | M8: 一人語り（放送・説明・留守電） | N8: W19／W15／W09 | Q8: ラジオで、女の人が話しています。 | R8: 123 | S8: 1 | T8: 1 | U8: 4 | V8: 走ることが生活の一部になったこと
A9: L008 | B9: N3 | C9: 概要理解 | D9: S25 | E9: 放送・ラジオ／テレビ | F9: T09 | G9: 仕事・アルバイト | H9: F13 | I9: 意見を述べる | J9: D09 | K9: 譲歩からの転換：〜だけど〜 | L9: R10 | M9: 一人語り（放送・説明・留守電） | N9: W09／W15／W13 | Q9: テレビで、店の人が話しています。 | R9: 129 | S9: 1 | T9: 1 | U9: 4 | V9: 新鮮で安心な野菜を売ることへのこだわり
A10: L009 | B10: N3 | C10: 概要理解 | D10: S07 | E10: 職場・同僚どうし | F10: T22 | G10: 仕事のやり方・段取り | H10: F07 | I10: 助言する／指示する | J10: D09 | K10: 譲歩からの転換：〜だけど〜 | L10: R06 | M10: 同僚どうし | N10: W09／W09／W15 | Q10: 会社で、先輩が新入社員に話しています。 | R10: 121 | S10: 1 | T10: 1 | U10: 4 | V10: 聞いたことは必ずメモを取ること
A11: L010 | B11: N3 | C11: 発話表現 | D11: S16 | E11: 駅・空港・交通機関 | F11: T17 | G11: マナー・ルール | H11: F11 | I11: 申し出る／引き受ける | J11: D12 | K11: 場面から適切な一言（発話表現） | L11: R02 | M11: 友人どうし | N11: W12／W08／W15 | O11: U03 | P11: 申し出る・手伝う | Q11: 電車の中で、お年寄りが立っています。あなたは席に座っています。席をゆずりたいです。 | R11: 0 | S11: 0 | T11: 0 | U11: 4 | V11: よかったら、どうぞ座ってください。
A12: L011 | B12: N3 | C12: 発話表現 | D12: S02 | E12: 友人・知人どうし | F12: T12 | G12: 家族・人間関係 | H12: F08 | I12: 謝る／弁明する | J12: D12 | K12: 場面から適切な一言（発話表現） | L12: R02 | M12: 友人どうし | N12: W20／W09／W15 | O12: U05 | P12: 謝る | Q12: 友だちに借りた本を、うっかり少し破いてしまいました。本を返すとき、正直に伝えます。 | R12: 0 | S12: 0 | T12: 0 | U12: 4 | V12: ごめんなさい、本を少し破いてしまいました。
A13: L012 | B13: N3 | C13: 発話表現 | D13: S16 | E13: 駅・空港・交通機関 | F13: T06 | G13: 交通・移動 | H13: F11 | I13: 申し出る／引き受ける | J13: D12 | K13: 場面から適切な一言（発話表現） | L13: R02 | M13: 友人どうし | N13: W12／W12／W08 | O13: U03 | P13: 申し出る・手伝う | Q13: 駅で、道が分からず困っている様子の人がいます。あなたは手伝いたいです。 | R13: 0 | S13: 0 | T13: 0 | U13: 4 | V13: どうかしましたか。お手伝いしましょうか。
A14: L013 | B14: N3 | C14: 即時応答 | D14: S02 | E14: 友人・知人どうし | F14: T20 | G14: メディア・情報 | H14: F01 | I14: 依頼する／依頼を受ける | J14: D11 | K14: 即応：短い発話への応答 | L14: R02 | M14: 友人どうし | N14: W12／W20／W13 | R14: 19 | S14: 1 | T14: 1 | U14: 4 | V14: うん、いいよ。読み終わったら持ってくるね。
A15: L014 | B15: N3 | C15: 即時応答 | D15: S11 | E15: 店・買い物／商品選び | F15: T02 | G15: 買い物・値段 | H15: F11 | I15: 申し出る／引き受ける | J15: D11 | K15: 即応：短い発話への応答 | L15: R07 | M15: 店員と客 | N15: W12／W20／W13 | R15: 18 | S15: 1 | T15: 1 | U15: 4 | V15: あ、シャツを探しているんですが。
A16: L015 | B16: N3 | C16: 即時応答 | D16: S07 | E16: 職場・同僚どうし | F16: T22 | G16: 仕事のやり方・段取り | H16: F01 | I16: 依頼する／依頼を受ける | J16: D11 | K16: 即応：短い発話への応答 | L16: R05 | M16: 上司と部下 | N16: W08／W12／W12 | R16: 28 | S16: 1 | T16: 1 | U16: 4 | V16: はい、すぐに直します。
A17: L016 | B17: N3 | C17: 課題理解 | D17: S03 | E17: 学校・教室／授業 | F17: T08 | G17: 学校生活・勉強 | H17: F07 | I17: 助言する／指示する | J17: D01 | K17: 条件つき先行：Aの前にBをする | L17: R03 | M17: 先生と学生 | N17: W01／W15／W15 | Q17: 学校で、先生と学生が話しています。学生は、このあとまず何をしますか。 | R17: 121 | S17: 4 | T17: 2 | U17: 4 | V17: 発表の内容を先生に見せる
A18: L017 | B18: N3 | C18: 課題理解 | D18: S01 | E18: 家庭・家族の会話 | F18: T02 | G18: 買い物・値段 | H18: F01 | I18: 依頼する／依頼を受ける | J18: D01 | K18: 条件つき先行：Aの前にBをする | L18: R01 | M18: 家族 | N18: W01／W01／W13 | Q18: 家で、母と息子が話しています。息子は、まず何をしますか。 | R18: 109 | S18: 4 | T18: 2 | U18: 4 | V18: 冷蔵庫の中を見る
A19: L018 | B19: N3 | C19: 課題理解 | D19: S07 | E19: 職場・同僚どうし | F19: T22 | G19: 仕事のやり方・段取り | H19: F01 | I19: 依頼する／依頼を受ける | J19: D01 | K19: 条件つき先行：Aの前にBをする | L19: R06 | M19: 同僚どうし | N19: W01／W01／W15 | Q19: 会社で、女の人と男の人が話しています。男の人は、まず何をしますか。 | R19: 107 | S19: 4 | T19: 2 | U19: 4 | V19: エアコンをつける
A20: L019 | B20: N3 | C20: ポイント理解 | D20: S12 | E20: 店・注文／予約 | F20: T01 | G20: 予定・約束・時間 | H20: F18 | I20: 予定を調整する | J20: D05 | K20: 表面の理由と本当の理由 | L20: R07 | M20: 店員と客 | N20: W04／W15／W15 | Q20: 電話で、男の人とレストランの店員が話しています。男の人は、どうして予約の時間を変えますか。 | R20: 120 | S20: 4 | T20: 2 | U20: 4 | V20: 友だちの電車が遅れているから
A21: L020 | B21: N3 | C21: ポイント理解 | D21: S02 | E21: 友人・知人どうし | F21: T07 | G21: 住まい・部屋 | H21: F16 | I21: 説明する | J21: D09 | K21: 譲歩からの転換：〜だけど〜 | L21: R02 | M21: 友人どうし | N21: W08／W15／W15 | Q21: 女の人と男の人が話しています。女の人は、どうして引っ越しますか。 | R21: 116 | S21: 4 | T21: 2 | U21: 4 | V21: 今の部屋がせまいから
A22: L021 | B22: N3 | C22: ポイント理解 | D22: S07 | E22: 職場・同僚どうし | F22: T01 | G22: 予定・約束・時間 | H22: F16 | I22: 説明する | J22: D05 | K22: 表面の理由と本当の理由 | L22: R06 | M22: 同僚どうし | N22: W04／W15／W15 | Q22: 会社で、男の人と女の人が話しています。男の人は、どうして遅刻しましたか。 | R22: 82 | S22: 3 | T22: 2 | U22: 4 | V22: 財布を取りに家に戻ったから
A23: L022 | B23: N3 | C23: 概要理解 | D23: S20 | E23: 図書館・公共施設 | F23: T17 | G23: マナー・ルール | H23: F07 | I23: 助言する／指示する | J23: D14 | K23: 説明のあとに注意点 | L23: R10 | M23: 一人語り（放送・説明・留守電） | N23: W15／W15／W13 | Q23: 図書館で、係の人が話しています。 | R23: 123 | S23: 1 | T23: 1 | U23: 4 | V23: 図書館を利用するときの決まり
A24: L023 | B24: N3 | C24: 概要理解 | D24: S25 | E24: 放送・ラジオ／テレビ | F24: T11 | G24: 旅行・観光 | H24: F19 | I24: 感想・気持ちを述べる | J24: D08 | K24: 対比：前と今／自分と他人 | L24: R10 | M24: 一人語り（放送・説明・留守電） | N24: W08／W09／W15 | Q24: 女の人が話しています。 | R24: 137 | S24: 1 | T24: 1 | U24: 4 | V24: 一人旅は思ったよりよい経験だったこと
A25: L024 | B25: N3 | C25: 概要理解 | D25: S03 | E25: 学校・教室／授業 | F25: T08 | G25: 学校生活・勉強 | H25: F07 | I25: 助言する／指示する | J25: D14 | K25: 説明のあとに注意点 | L25: R03 | M25: 先生と学生 | N25: W08／W15／W19 | Q25: 学校で、先生が話しています。 | R25: 129 | S25: 1 | T25: 1 | U25: 4 | V25: 自分で調べる習慣をつけること
A26: L025 | B26: N3 | C26: 発話表現 | D26: S03 | E26: 学校・教室／授業 | F26: T08 | G26: 学校生活・勉強 | H26: F01 | I26: 依頼する／依頼を受ける | J26: D12 | K26: 場面から適切な一言（発話表現） | L26: R04 | M26: 学生どうし | N26: W20／W12／W13 | O26: U01 | P26: 依頼する | Q26: 授業中、ペンを忘れました。となりの友だちから借りたいです。 | R26: 0 | S26: 0 | T26: 0 | U26: 4 | V26: ごめん、ペンを一本貸してくれない？
A27: L026 | B27: N3 | C27: 発話表現 | D27: S07 | E27: 職場・同僚どうし | F27: T01 | G27: 予定・約束・時間 | H27: F08 | I27: 謝る／弁明する | J27: D12 | K27: 場面から適切な一言（発話表現） | L27: R06 | M27: 同僚どうし | N27: W08／W12／W13 | O27: U05 | P27: 謝る | Q27: 会議に少し遅れてしまいました。部屋に入るとき、何と言いますか。 | R27: 0 | S27: 0 | T27: 0 | U27: 4 | V27: 遅れて申し訳ありません。
A28: L027 | B28: N3 | C28: 発話表現 | D28: S11 | E28: 店・買い物／商品選び | F28: T02 | G28: 買い物・値段 | H28: F12 | I28: 許可を求める／与える | J28: D12 | K28: 場面から適切な一言（発話表現） | L28: R07 | M28: 店員と客 | N28: W20／W20／W13 | O28: U02 | P28: 許可を求める | Q28: 服の店で、気に入ったシャツがありました。着てみたいです。店員に何と言いますか。 | R28: 0 | S28: 0 | T28: 0 | U28: 4 | V28: すみません、これを試着してもいいですか。
A29: L028 | B29: N3 | C29: 即時応答 | D29: S02 | E29: 友人・知人どうし | F29: T12 | G29: 家族・人間関係 | H29: F10 | I29: お礼を言う／ねぎらう | J29: D11 | K29: 即応：短い発話への応答 | L29: R02 | M29: 友人どうし | N29: W12／W11／W11 | R29: 23 | S29: 1 | T29: 1 | U29: 4 | V29: いいえ、どういたしまして。
A30: L029 | B30: N3 | C30: 即時応答 | D30: S02 | E30: 友人・知人どうし | F30: T03 | G30: 食事・料理 | H30: F03 | I30: 提案する／すすめる | J30: D11 | K30: 即応：短い発話への応答 | L30: R02 | M30: 友人どうし | N30: W11／W13／W20 | R30: 23 | S30: 1 | T30: 1 | U30: 4 | V30: うん、いいね。行こう。
A31: L030 | B31: N3 | C31: 即時応答 | D31: S07 | E31: 職場・同僚どうし | F31: T09 | G31: 仕事・アルバイト | H31: F11 | I31: 申し出る／引き受ける | J31: D11 | K31: 即応：短い発話への応答 | L31: R06 | M31: 同僚どうし | N31: W11／W12／W20 | R31: 29 | S31: 1 | T31: 1 | U31: 4 | V31: ありがとう、助かります。お願いします。
A32: L031 | B32: N3 | C32: 即時応答 | D32: S02 | E32: 友人・知人どうし | F32: T07 | G32: 住まい・部屋 | H32: F01 | I32: 依頼する／依頼を受ける | J32: D11 | K32: 即応：短い発話への応答 | L32: R02 | M32: 友人どうし | N32: W11／W08／W20 | R32: 17 | S32: 1 | T32: 1 | U32: 4 | V32: うん、いいよ。何時に行けばいい？
A33: L032 | B33: N3 | C33: 即時応答 | D33: S07 | E33: 職場・同僚どうし | F33: T09 | G33: 仕事・アルバイト | H33: F10 | I33: お礼を言う／ねぎらう | J33: D11 | K33: 即応：短い発話への応答 | L33: R06 | M33: 同僚どうし | N33: W12／W11／W13 | R33: 9 | S33: 1 | T33: 1 | U33: 4 | V33: お疲れさまでした。
A34: L033 | B34: N3 | C34: 即時応答 | D34: S16 | E34: 駅・空港・交通機関 | F34: T17 | G34: マナー・ルール | H34: F04 | I34: 確認する／念を押す | J34: D11 | K34: 即応：短い発話への応答 | L34: R02 | M34: 友人どうし | N34: W20／W13／W13 | R34: 18 | S34: 1 | T34: 1 | U34: 4 | V34: ええ、どうぞ。
A35: L034 | B35: N3 | C35: 即時応答 | D35: S03 | E35: 学校・教室／授業 | F35: T07 | G35: 住まい・部屋 | H35: F12 | I35: 許可を求める／与える | J35: D11 | K35: 即応：短い発話への応答 | L35: R02 | M35: 友人どうし | N35: W11／W20／W11 | R35: 12 | S35: 1 | T35: 1 | U35: 4 | V35: ええ、どうぞ。
A36: L035 | B36: N3 | C36: 即時応答 | D36: S14 | E36: レストラン・飲食店 | F36: T03 | G36: 食事・料理 | H36: F03 | I36: 提案する／すすめる | J36: D11 | K36: 即応：短い発話への応答 | L36: R07 | M36: 店員と客 | N36: W11／W12／W13 | R36: 16 | S36: 1 | T36: 1 | U36: 4 | V36: いえ、もう十分です。ありがとうございます。
A37: L036 | B37: N3 | C37: 即時応答 | D37: S16 | E37: 駅・空港・交通機関 | F37: T06 | G37: 交通・移動 | H37: F16 | I37: 説明する | J37: D11 | K37: 即応：短い発話への応答 | L37: R02 | M37: 友人どうし | N37: W13／W20／W20 | R37: 16 | S37: 1 | T37: 1 | U37: 4 | V37: 歩いて十分ぐらいです。
A38: L037 | B38: N3 | C38: 即時応答 | D38: S03 | E38: 学校・教室／授業 | F38: T08 | G38: 学校生活・勉強 | H38: F19 | I38: 感想・気持ちを述べる | J38: D11 | K38: 即応：短い発話への応答 | L38: R04 | M38: 学生どうし | N38: W11／W08／W20 | R38: 13 | S38: 1 | T38: 1 | U38: 4 | V38: うーん、あまりできなかったよ。
A39: L038 | B39: N3 | C39: 即時応答 | D39: S07 | E39: 職場・同僚どうし | F39: T22 | G39: 仕事のやり方・段取り | H39: F01 | I39: 依頼する／依頼を受ける | J39: D11 | K39: 即応：短い発話への応答 | L39: R05 | M39: 上司と部下 | N39: W13／W20／W13 | R39: 15 | S39: 1 | T39: 1 | U39: 4 | V39: はい、すぐにやります。
A40: L039 | B40: N3 | C40: 即時応答 | D40: S09 | E40: 職場・電話／来客対応 | F40: T13 | G40: 手続き・申し込み | H40: F01 | I40: 依頼する／依頼を受ける | J40: D11 | K40: 即応：短い発話への応答 | L40: R08 | M40: 窓口と利用者 | N40: W11／W20／W13 | R40: 15 | S40: 1 | T40: 1 | U40: 4 | V40: 田中と申します。
...

Sheet 20_読解
A1: ID | B1: 級 | C1: 大問 | D1: ジャンル | E1: ジャンル名 | F1: 話題 | G1: 話題名 | H1: 展開型 | I1: 展開型名 | J1: 読解技法 | K1: 読解技法名 | L1: 誤答型 | M1: 資料 | N1: 本文の書き出し | O1: 設問文 | P1: 本文字数 | Q1: 選択肢数 | R1: 正解
A2: R001 | B2: N3 | C2: 内容理解（短文） | D2: G05 | E2: 案内文・お知らせ | F2: T13 | G2: 手続き・申し込み | H2: D14 | I2: 説明のあとに注意点 | J2: K02 | K2: 言い換え | L2: W07／W08／W08 | N2: つぎの文章を読んで、質問に答えてください。答えは、１・２・３・４から、いちばんい | O2: このお知らせで正しいのはどれですか。 | P2: 248 | Q2: 4 | R2: 18日から図書館が普通に使えるようになる。
A3: R002 | B3: N3 | C3: 内容理解（短文） | D3: G04 | E3: 物語・体験談 | F3: T11 | G3: 旅行・観光 | H3: D09 | I3: 譲歩からの転換：〜だけど〜 | J3: K05 | K3: 理由の特定 | L3: W09／W08／W15 | N3: つぎの文章を読んで、質問に答えてください。答えは、１・２・３・４から、いちばんい | O3: 筆者が最初不安だった理由は何ですか。 | P3: 247 | Q3: 4 | R3: 一人旅でフランス語もできなかったから
A4: R003 | B4: N3 | C4: 内容理解（短文） | D4: G06 | E4: メール・手紙 | F4: T08 | G4: 学校生活・勉強 | H4: D07 | I4: 前置きのあと本題 | J4: K06 | K4: 主体・対象の特定（だれが・何を） | L4: W09／W13／W15 | N4: つぎの文章を読んで、質問に答えてください。答えは、１・２・３・４から、いちばんい | O4: リーさんは何をお願いしていますか。 | P4: 246 | Q4: 4 | R4: 友人に授業の資料を渡してもらうこと
A5: R004 | B5: N3 | C5: 内容理解（短文） | D5: G03 | E5: 意見文 | F5: T20 | G5: メディア・情報 | H5: D08 | I5: 対比：前と今／自分と他人 | J5: K05 | K5: 理由の特定 | L5: W15／W15／W15 | N5: つぎの文章を読んで、質問に答えてください。答えは、１・２・３・４から、いちばんい | O5: 筆者が紙の本を好む理由は何ですか。 | P5: 235 | Q5: 4 | R5: 紙ならではの感覚や楽しみがあるから
A6: R005 | B6: N3 | C6: 内容理解（短文） | D6: G10 | E6: メモ・伝言 | F6: T01 | G6: 予定・約束・時間 | H6: D02 | I6: 予定の変更：都合が悪くなって順序が変わる | J6: K06 | K6: 主体・対象の特定（だれが・何を） | L6: W03／W02／W08 | N6: つぎの文章を読んで、質問に答えてください。答えは、１・２・３・４から、いちばんい | O6: このメモを読んで、田中さんは今日の５時までに何をしなければなりませんか。 | P6: 232 | Q6: 4 | R6: 佐藤さんに電話をする
A7: R006 | B7: N3 | C7: 内容理解（短文） | D7: G05 | E7: 案内文・お知らせ | F7: T07 | G7: 住まい・部屋 | H7: D14 | I7: 説明のあとに注意点 | J7: K06 | K7: 主体・対象の特定（だれが・何を） | L7: W15／W15／W13 | N7: つぎの文章を読んで、質問に答えてください。答えは、１・２・３・４から、いちばんい | O7: このお知らせで、住民は何をしておいたほうがいいですか。 | P7: 230 | Q7: 4 | R7: 工事の前の日に水を用意しておく
A8: R007 | B8: N3 | C8: 内容理解（短文） | D8: G06 | E8: メール・手紙 | F8: T01 | G8: 予定・約束・時間 | H8: D02 | I8: 予定の変更：都合が悪くなって順序が変わる | J8: K02 | K8: 言い換え | L8: W08／W08／W07 | N8: つぎの文章を読んで、質問に答えてください。答えは、１・２・３・４から、いちばんい | O8: バーベキューについて、正しいものはどれですか。 | P8: 240 | Q8: 4 | R8: 雨のため、場所が木村さんの家に変わった
A9: R008 | B9: N3 | C9: 内容理解（短文） | D9: G04 | E9: 物語・体験談 | F9: T03 | G9: 食事・料理 | H9: D09 | I9: 譲歩からの転換：〜だけど〜 | J9: K05 | K9: 理由の特定 | L9: W08／W15／W15 | N9: つぎの文章を読んで、質問に答えてください。答えは、１・２・３・４から、いちばんい | O9: この人はどうしてうれしかったのですか。 | P9: 235 | Q9: 4 | R9: 母にカレーをほめてもらったから
A10: R009 | B10: N3 | C10: 内容理解（短文） | D10: G05 | E10: 案内文・お知らせ | F10: T13 | G10: 手続き・申し込み | H10: D14 | I10: 説明のあとに注意点 | J10: K12 | K10: 順序・手順の把握 | L10: W08／W07／W15 | N10: つぎの文章を読んで、質問に答えてください。答えは、１・２・３・４から、いちばんい | O10: この読書会に参加するには、どうすればいいですか。 | P10: 227 | Q10: 4 | R10: 前の週の金曜日までに受付で申し込む
A11: R010 | B11: N3 | C11: 内容理解（短文） | D11: G02 | E11: エッセイ・随筆 | F11: T04 | G11: 健康・体調・病気 | H11: D08 | I11: 対比：前と今／自分と他人 | J11: K09 | K11: 要約・主旨 | L11: W11／W08／W08 | N11: つぎの文章を読んで、質問に答えてください。答えは、１・２・３・４から、いちばんい | O11: この人が一番言いたいことは何ですか。 | P11: 236 | Q11: 4 | R11: 毎日の散歩という習慣が生活をよくした
A12: R011 | B12: N3 | C12: 内容理解（短文） | D12: G06 | E12: メール・手紙 | F12: T13 | G12: 手続き・申し込み | H12: D07 | I12: 前置きのあと本題 | J12: K06 | K12: 主体・対象の特定（だれが・何を） | L12: W15／W13／W17 | N12: つぎの文章を読んで、質問に答えてください。答えは、１・２・３・４から、いちばんい | O12: 伊藤さんはこのメールで何を頼んでいますか。 | P12: 243 | Q12: 4 | R12: かさが店にあるか教えてほしい
A13: R012 | B13: N3 | C13: 内容理解（短文） | D13: G05 | E13: 案内文・お知らせ | F13: T10 | G13: 趣味・スポーツ | H13: D14 | I13: 説明のあとに注意点 | J13: K02 | K13: 言い換え | L13: W08／W11／W07 | N13: つぎの文章を読んで、質問に答えてください。答えは、１・２・３・４から、いちばんい | O13: このお知らせの内容として、正しいものはどれですか。 | P13: 230 | Q13: 4 | R13: 月曜日はプールが一日中使えない
... A56: R055 | B56: N3 | C56: 内容理解（長文） | D56: G02 | E56: エッセイ・随筆 | F56: T09 | G56: 仕事・アルバイト | H56: D08 | I56: 対比：前と今／自分と他人 | J56: K09 | K56: 要約・主旨 | L56: W16／W15／W09 | N56: つぎの文章を読んで、質問に答えてください。答えは、１・２・３・４から、いちばんい | O56: この文章で筆者が最も言いたいことは何か。 | P56: 656 | Q56: 4 | R56: わからないことは、勇気を出してはっきり伝えることが大
A57: R056 | B57: N3 | C57: 情報検索 | D57: G07 | E57: 広告・チラシ | F57: T13 | G57: 手続き・申し込み | H57: D06 | I57: 条件の突き合わせ：条件に合う一つを選ぶ | J57: K10 | K57: 条件の照合（情報検索） | L57: W14／W14／W18 | M57: sakura | N57: 右のページを見て、下の質問に答えてください。答えは、１・２・３・４から、いちばん | O57: ワンさんはN3対策のため合計5,000円以下でできるだけ多くの講座を受けたいです。最もよい組み合わせはどれですか。 | P57: 56 | Q57: 4 | R57: ③と⑤
A58: R057 | B58: N3 | C58: 情報検索 | D58: G07 | E58: 広告・チラシ | F58: T13 | G58: 手続き・申し込み | H58: D06 | I58: 条件の突き合わせ：条件に合う一つを選ぶ | J58: K10 | K58: 条件の照合（情報検索） | L58: W15／W14／W15 | M58: sakura | N58: 右のページを見て、下の質問に答えてください。答えは、１・２・３・４から、いちばん | O58: キムさんは10月18日に2つの講座を受けたいです。申し込み方法と受けられる講座の組み合わせはどれですか。 | P58: 56 | Q58: 4 | R58: メールで申し込む。③と④を受けられる。
A59: R058 | B59: N3 | C59: 情報検索 | D59: G07 | E59: 広告・チラシ | F59: T16 | G59: 地域・まちの行事 | H59: D06 | I59: 条件の突き合わせ：条件に合う一つを選ぶ | J59: K10 | K59: 条件の照合（情報検索） | L59: W18／W14／W18 | M59: event | N59: 右のページを見て、下の質問に答えてください。答えは、１・２・３・４から、いちばん | O59: アンさんは料理が好きです。週末に参加できるイベントを探しています。無料か安いものがいいです。参加できるイベントはどれです | P59: 56 | Q59: 4 | R59: ①と③
A60: R059 | B60: N3 | C60: 情報検索 | D60: G07 | E60: 広告・チラシ | F60: T16 | G60: 地域・まちの行事 | H60: D06 | I60: 条件の突き合わせ：条件に合う一つを選ぶ | J60: K10 | K60: 条件の照合（情報検索） | L60: W14／W14／W07 | M60: event | N60: 右のページを見て、下の質問に答えてください。答えは、１・２・３・４から、いちばん | O60: リーさんは子ども（5歳）と一緒に参加できるイベントを探しています。子どもでも楽しめるものはどれですか。 | P60: 56 | Q60: 4 | R60: ③フリーマーケット
A61: R060 | B61: N3 | C61: 情報検索 | D61: G07 | E61: 広告・チラシ | F61: T16 | G61: 地域・まちの行事 | H61: D06 | I61: 条件の突き合わせ：条件に合う一つを選ぶ | J61: K10 | K61: 条件の照合（情報検索） | L61: W14／W07／W14 | M61: event | N61: 右のページを見て、下の質問に答えてください。答えは、１・２・３・４から、いちばん | O61: タナカさんは平日の夕方しか時間がありません。参加できるイベントはどれですか。 | P61: 56 | Q61: 4 | R61: ④だけ
A62: R061 | B62: N3 | C62: 情報検索 | D62: G05 | E62: 案内文・お知らせ | F62: T13 | G62: 手続き・申し込み | H62: D06 | I62: 条件の突き合わせ：条件に合う一つを選ぶ | J62: K10 | K62: 条件の照合（情報検索） | L62: W14／W14／W07 | M62: shisetsu | N62: 右のページを見て、下の質問に答えてください。答えは、１・２・３・４から、いちばん | O62: ヤンさんは会議室を3時間借りたいです。20人で使います。最も安く借りられる部屋はどれですか。 | P62: 56 | Q62: 4 | R62: 中会議室（B）
A63: R062 | B63: N3 | C63: 情報検索 | D63: G05 | E63: 案内文・お知らせ | F63: T13 | G63: 手続き・申し込み | H63: D06 | I63: 条件の突き合わせ：条件に合う一つを選ぶ | J63: K10 | K63: 条件の照合（情報検索） | L63: W07／W07／W07 | M63: shisetsu | N63: 右のページを見て、下の質問に答えてください。答えは、１・２・３・４から、いちばん | O63: チェンさんは日曜日の午前10時から午後5時まで大会議室を借りたいです。何円払いますか。 | P63: 56 | Q63: 4 | R63: 14,000円
A64: R063 | B64: N3 | C64: 情報検索 | D64: G05 | E64: 案内文・お知らせ | F64: T13 | G64: 手続き・申し込み | H64: D06 | I64: 条件の突き合わせ：条件に合う一つを選ぶ | J64: K10 | K64: 条件の照合（情報検索） | L64: W07／W07／W07 | M64: shisetsu | N64: 右のページを見て、下の質問に答えてください。答えは、１・２・３・４から、いちばん | O64: パクさんは来週の水曜日に会議室を使いたいです。いつまでに予約すればいいですか。 | P64: 56 | Q64: 4 | R64: 使いたい日の3日前まで
A65: R064 | B65: N3 | C65: 情報検索 | D65: G05 | E65: 案内文・お知らせ | F65: T13 | G65: 手続き・申し込み | H65: D06 | I65: 条件の突き合わせ：条件に合う一つを選ぶ | J65: K10 | K65: 条件の照合（情報検索） | L65: W19／W18／W15 | M65: shisetsu | N65: 右のページを見て、下の質問に答えてください。答えは、１・２・３・４から、いちばん | O65: リンさんは飲食禁止のルールについて知りたいです。正しいのはどれですか。 | P65: 56 | Q65: 4 | R65: 飲み物は持ち込めますが食べ物は禁止です。
A66: R065 | B66: N3 | C66: 情報検索 | D66: G05 | E66: 案内文・お知らせ | F66: T13 | G66: 手続き・申し込み | H66: D06 | I66: 条件の突き合わせ：条件に合う一つを選ぶ | J66: K10 | K66: 条件の照合（情報検索） | L66: W07／W07／W07 | M66: shisetsu | N66: 右のページを見て、下の質問に答えてください。答えは、１・２・３・４から、いちばん | O66: ムンさんは日曜日の午後に50人で集まれる部屋を3時間借りたいです。最低いくら払いますか。 | P66: 56 | Q66: 4 | R66: 6,000円
A67: R066 | B67: N3 | C67: 情報検索 | D67: G07 | E67: 広告・チラシ | F67: T10 | G67: 趣味・スポーツ | H67: D06 | I67: 条件の突き合わせ：条件に合う一つを選ぶ | J67: K10 | K67: 条件の照合（情報検索） | L67: W07／W07／W07 | M67: eiga | N67: 右のページを見て、下の質問に答えてください。答えは、１・２・３・４から、いちばん | O67: キムさんは午後５時（17:00）から始まる映画を見たいです。どの作品を見ますか。 | P67: 56 | Q67: 4 | R67: やまの きせつ
A68: R067 | B68: N3 | C68: 情報検索 | D68: G07 | E68: 広告・チラシ | F68: T10 | G68: 趣味・スポーツ | H68: D06 | I68: 条件の突き合わせ：条件に合う一つを選ぶ | J68: K10 | K68: 条件の照合（情報検索） | L68: W07／W07／W07 | M68: eiga | N68: 右のページを見て、下の質問に答えてください。答えは、１・２・３・４から、いちばん | O68: ワンさんの子ども（こども料金）が「まちの ひみつ」を見ます。いくら払いますか。 | P68: 56 | Q68: 4 | R68: 600円
... A102: R101 | B102: N3 | C102: 情報検索 | D102: G05 | E102: 案内文・お知らせ | F102: T10 | G102: 趣味・スポーツ | H102: D06 | I102: 条件の突き合わせ：条件に合う一つを選ぶ | J102: K10 | K102: 条件の照合（情報検索） | L102: W18／W15／W15 | M102: pool | N102: 右のページを見て、下の質問に答えてください。答えは、１・２・３・４から、いちばん | O102: プールに入るとき、必ず用意しなければならないものは何ですか。 | P102: 56 | Q102: 4 | R102: 水着と水泳帽子

Sheet 30_語彙
A1: N3 文字・語彙 3,255問のいまの姿
A2: 一問ずつの分類はこれから。まずは大問ごとの数字と、公式との差だけを置く。行を足すときは 01_分類マスタ のコードを使う。
A4: 大問 | B4: 問数 | C4: 選択肢字数 | D4: 公式 | E4: 肢の長短差 | F4: 公式 | G4: 4肢同字数 | H4: 公式 | I4: メモ
A5: 漢字読み | B5: 1854 | C5: 3.4 | D5: 4.1 | E5: 0.2 | F5: 0.6 | G5: 0.823 | H5: 0.625
A6: 表記 | B6: 343 | C6: 2.2 | D6: 2.2 | E6: 0 | F6: 0 | G6: 0.994 | H6: 1 | I6: 公式は6問すべて長短差0＝必ず同字数
A7: 文脈規定 | B7: 439 | C7: 2.7 | D7: 2.9 | E7: 0.7 | F7: 0.5 | G7: 0.54 | H7: 0.727
A8: 言い換え類義 | B8: 292 | C8: 5.7 | D8: 6.3 | E8: 1.5 | F8: 2.4 | G8: 0.37 | H8: 0.2
A9: 用法 | B9: 327 | C9: 19.1 | D9: 27.8 | E9: 3.3 | F9: 4.8 | G9: 0 | H9: 0
A11: ― 一問ずつ分類する場合の見出し（例文のある問題だけ。漢字読みは語彙リストで管理）―
A12: ID | B12: 級 | C12: 大問 | D12: 対象語 | E12: 品詞 | F12: 話題 | G12: 話題名 | H12: 誤答型 | I12: 例文の要約
A13: N3-語彙-文脈規定-0001 | B13: N3 | C13: 文脈規定 | D13: 特長 | E13: 名詞 | F13: T14 | G13: 道具・機械の使い方 | H13: W25／W13／W15 | I13: （記入例。この行は消してください）

Sheet 40_文法
A1: N3 文法 300問のいまの姿
A2: 一問ずつの分類はこれから。文型は「〜ばかりだ」のように、その問題が問うている形式を書く。
A4: 大問 | B4: 問数 | C4: 選択肢字数 | D4: 公式 | E4: 肢の長短差 | F4: 公式 | G4: 会話形式の割合 | H4: メモ
A5: 文の文法1 | B5: 100 | C5: 4 | D5: 6.2 | E5: 1.5 | F5: 2.4 | G5: 38.5%（公式） | H5: 公式は13問中5問が会話形式
A6: 文の文法2 | B6: 100 | C6: 3.3 | D6: 5.1 | E6: 2.1 | F6: 4.2 | G6: 20.0%（公式）
A7: 文章の文法 | B7: 100 | C7: 3.2 | D7: 5.8 | E7: 1.2 | F7: 1.8 | H7: 公式の本文は468字・5段落
A9: ― 一問ずつ分類する場合の見出し ―
A10: ID | B10: 級 | C10: 大問 | D10: 文型 | E10: 話題 | F10: 話題名 | G10: 誤答型 | H10: 例文の要約
A11: N3-文法-文の文法1-0001 | B11: N3 | C11: 文の文法1 | D11: 〜として | E11: T09 | F11: 仕事・アルバイト | G11: W22／W13／W15 | H11: （記入例。この行は消してください）

Sheet 90_重複と偏り
A1: 分類作業で見つかった重複・偏り・不備（2026-08-12 時点）
A2: 差し替えや作問の優先順位を決めるための一覧。対応したら「対応」列に印を入れる。
A4: 種別 | B4: 大問 | C4: 対象 | D4: 内容 | E4: 重さ | F4: 対応
A5: 不備 | B5: 読解 情報検索 | C5: R056（sakura） | D5: 「5,000円以下でできるだけ多く」だが、正解③+⑤（3,500円・2講座）と肢2①+⑤（4,500円・2講座）が同数で両方条件を満たす。「できるだけ安く」が設問文に無い | E5: 大
A6: 不備 | B6: 読解 情報検索 | C6: R059（event） | D6: 「子ども（5歳）と一緒に参加できる」だが、チラシに年齢・子ども可否の記載が無い。消去法でしか解けない | E6: 大
A7: 不備 | B7: 読解 情報検索 | C7: R060（event） | D7: 正解の映画鑑賞会が19:00〜21:00。「平日の夕方」と言えるか微妙 | E7: 中
A8: 不備 | B8: 読解 情報検索 | C8: R061（shisetsu） | D8: 肢1「小会議室(A)×3」＝複数室同時貸出の可否が資料に無い | E8: 中
A9: 偏り | B9: 聴解ぜんたい | C9: 場面 | D9: S02友人49問・S07職場39問で182問の半数近く。1場面20問以下にしたい | E9: 大
A10: 偏り | B10: 聴解ぜんたい | C10: 未使用の場面9つ | D10: S04学校事務／S05部活／S17役所／S18銀行・郵便局／S19引っ越し／S22スポーツ教室／S24イベント／S27留守番電話／S28ネット・メール | E10: 大
A11: 偏り | B11: 読解 情報検索 | C11: 資料 | D11: 46問がわずか9種類の資料の使い回し（1資料で最大6問）。資料を増やす | E11: 大
A12: 偏り | B12: 読解ぜんたい | C12: ジャンル | D12: G08掲示・貼り紙とG09記事・レポートがゼロ。G10メモ・伝言も少ない | E12: 中
A13: 偏り | B13: 聴解ぜんたい | C13: 誤答型 | D13: W15「本文にない情報」が聴解160件・読解70件で突出。消去法で消しやすい誤答が多い | E13: 中
A14: 偏り | B14: 聴解 課題理解ほか | C14: 展開型 | D14: D02予定の変更1問・D04分担1問・D13数量計算0問。公式にある型が当サイトにほぼ無い | E14: 中
A15: 分類の穴 | B15: 分類マスタ | C15: 機能F | D15: 「あいさつ・決まり文句」が無く分類係3人が同じ所で詰まった → F21として追加済み | E15: 小 | F15: 済 2026-08-12
A16: 要検討 | B16: 聴解 発話表現 | C16: イラスト | D16: 公式はイラストを見て答える。当サイトは文章の場面説明のみ。イラストを入れるか決める | E16: 大
A17: 要検討 | B17: 聴解 課題理解 | C17: イラスト選択肢 | D17: 公式は6問中1問が選択肢そのものがイラスト（ア〜エの組み合わせ）。当サイトにゼロ | E17: 中
A18: 完了 | B18: 聴解 発話表現・即時応答 | C18: 92問 | D18: 選択肢4つ→3つ。台本・音声・正解は一切触っていない。最長肢33.3%／34.0%に着地 | E18: 大 | F18: 済 2026-08-13
A19: 重複 | B19: 聴解 即時応答 | C19: 09／10／26 | D19: 正解が3問とも「ええ、どうぞ。」。発話は別（席・窓・本）だが、許可を求める→許可する の型が3回重なる。応答の言い方を分けたい | E19: 中
A20: 要検討 | B20: 聴解 即時応答 | C20: 10 | D20: rank Lで正解7字のため、誤答を6字以下にせざるを得ず長短差が2字止まり。正解の文を変えないと直せない | E20: 小
