Workbook

Sheet このファイルについて
A1: N5 語彙グループ分け（文字・語彙の問題づくり用）
A3: ・語彙データ出典：open-anki-jlpt-decks（tanos.co.uk 由来、CCライセンス）。
A4: ・JLPTは公式の語彙リストを公表していないため、これは一般的な目安リストです。
A5: ・グループは「品詞（形態素解析）＋意味のキーワード」で自動分類した第一案です。
A6: 一部は意味の取り違えで分類がずれることがあります（要確認・調整）。
A7: ・使い方：各回の出題で、各グループからバランスよく語を選ぶ／同じ語でも形式違いの問題を複数作る、の土台に。
A8: ・「その他の名詞」は分類しきれなかった名詞の受け皿です。必要に応じて細分してください。
A11: 【N5文型シートについて（2026-07-22 追加）】
A12: ・「N5文型」シート：N5レベルで学ぶ代表的な文型を、意味・機能ごとにグループ分けしてまとめたもの。
A13: ・文型は各種N5教材で共通して扱われる標準的な文法項目です（特定の教科書の索引・番号・本文は転記していません）。
A14: ・例文はすべてこのファイル用に作成したオリジナルです（著作権に配慮）。ひらがな中心のやさしい例にしています。
A15: ・「文型集計」シート：グループごとの文型数（COUNTIFで自動集計）。
... A23: ・各語はいちばん近い既存グループに割り当て、グループ内は読みの五十音順に並べています。

Sheet 語彙グループ別
A1: グループ | B1: 語 | C1: 読み | D1: 意味 | E1: 品詞 | F1: 備考
A2: 動詞 | B2: 会う | C2: あう | D2: to meet, to see | E2: 動詞
A3: 動詞 | B3: 開く | C3: あく | D3: to open, to become open | E3: 動詞
A4: 動詞 | B4: 開ける | C4: あける | D4: to open (v.t.) | E4: 動詞
A5: 動詞 | B5: 上げる | C5: あげる | D5: to raise, to lift | E5: 動詞
A6: 動詞 | B6: 遊ぶ | C6: あそぶ | D6: to play; to spend time pleasantly; to hang out | E6: 動詞
A7: 動詞 | B7: 浴びる | C7: あびる | D7: to bathe, to shower | E7: 動詞
A8: 動詞 | B8: 洗う | C8: あらう | D8: to wash | E8: 動詞
A9: 動詞 | B9: 在る | C9: ある | D9: to be, to have | E9: 動詞
A10: 動詞 | B10: 有る | C10: ある | D10: to be, to have | E10: 動詞
A11: 動詞 | B11: 歩く | C11: あるく | D11: to walk | E11: 動詞
A12: 動詞 | B12: 言う | C12: いう | D12: to say | E12: 動詞
A13: 動詞 | B13: 行く | C13: いく; ゆく | D13: to go | E13: 動詞
... A113: 動詞 | B113: コピーする | C113: コピーする | D113: to copy | E113: 動詞
A114: 動詞 | B114: 上がる | C114: あがる | D114: to go up | E114: 動詞 | F114: 追加
A115: 動詞 | B115: 受ける | C115: うける | D115: to take (a test/class) | E115: 動詞 | F115: 追加
A116: 動詞 | B116: 売れる | C116: うれる | D116: to sell (vi), to be sold | E116: 動詞 | F116: 追加
A117: 動詞 | B117: 怒る | C117: おこる | D117: to get angry | E117: 動詞 | F117: 追加
A118: 動詞 | B118: 聞こえる | C118: きこえる | D118: to be audible | E118: 動詞 | F118: 追加
A119: 動詞 | B119: くださる | C119: くださる | D119: to give (honorific) | E119: 動詞 | F119: 追加
A120: 動詞 | B120: 込む | C120: こむ | D120: to be crowded | E120: 動詞 | F120: 追加
A121: 動詞 | B121: 捨てる | C121: すてる | D121: to throw away | E121: 動詞 | F121: 追加
A122: 動詞 | B122: 伝える | C122: つたえる | D122: to convey, to tell | E122: 動詞 | F122: 追加
A123: 動詞 | B123: 通る | C123: とおる | D123: to pass through | E123: 動詞 | F123: 追加
A124: 動詞 | B124: 始める | C124: はじめる | D124: to begin (vt) | E124: 動詞 | F124: 追加
A125: 動詞 | B125: 払う | C125: はらう | D125: to pay | E125: 動詞 | F125: 追加
... A127: 動詞 | B127: わかす | C127: わかす | D127: to boil | E127: 動詞 | F127: 追加
A128: い形容詞 | B128: 青い | C128: あおい | D128: blue | E128: 形容詞
A129: い形容詞 | B129: 赤い | C129: あかい | D129: red | E129: 形容詞
A130: い形容詞 | B130: 明るい | C130: あかるい | D130: bright (in reference to personality or weather); cheerful | E130: 形容詞
A131: い形容詞 | B131: 暖かい | C131: あたたかい | D131: warm | E131: 形容詞
A132: い形容詞 | B132: 新しい | C132: あたらしい | D132: new | E132: 形容詞
A133: い形容詞 | B133: 暑い | C133: あつい | D133: hot (in reference to weather), warm | E133: 形容詞
A134: い形容詞 | B134: 熱い | C134: あつい | D134: hot (objects) | E134: 形容詞
A135: い形容詞 | B135: 厚い | C135: あつい | D135: kind, warm(hearted), thick, deep | E135: 形容詞
A136: い形容詞 | B136: 危ない | C136: あぶない | D136: dangerous, critical | E136: 形容詞
A137: い形容詞 | B137: 甘い | C137: あまい | D137: generous, sweet | E137: 形容詞
A138: い形容詞 | B138: いい; よい | C138: いい; よい | D138: good | E138: 形容詞
A139: い形容詞 | B139: 忙しい | C139: いそがしい | D139: busy (people, days) | E139: 形容詞
... A188: い形容詞 | B188: 悪い | C188: わるい | D188: bad, sinful; inferior | E188: 形容詞
...

Sheet N5文型
A1: グループ | B1: 文型 | C1: 意味・用法 | D1: 例文
A2: 助詞（格助詞） | B2: 〜は | C2: 主題（〜について言うと）を示す。 | D2: わたしは がくせいです。
A3: 助詞（格助詞） | B3: 〜が | C3: 主語や、好き・ある・できる等の対象を示す。 | D3: にほんごが わかります。
A4: 助詞（格助詞） | B4: 〜を | C4: 動作の対象（目的語）を示す。 | D4: ごはんを たべます。
A5: 助詞（格助詞） | B5: 〜を（通過） | C5: 通る場所・経路を示す。 | D5: こうえんを さんぽします。
A6: 助詞（格助詞） | B6: 〜に（場所） | C6: 存在する場所を示す。 | D6: つくえの うえに ほんが あります。
A7: 助詞（格助詞） | B7: 〜に（時） | C7: 動作が行われる時点を示す。 | D7: ７じに おきます。
A8: 助詞（格助詞） | B8: 〜に（帰着点） | C8: 到達点・方向を示す。 | D8: うちに かえります。
A9: 助詞（格助詞） | B9: 〜へ | C9: 移動の方向を示す。 | D9: がっこうへ いきます。
A10: 助詞（格助詞） | B10: 〜で（場所） | C10: 動作が行われる場所を示す。 | D10: としょかんで べんきょうします。
A11: 助詞（格助詞） | B11: 〜で（手段） | C11: 手段・道具・材料を示す。 | D11: バスで いきます。
A12: 助詞（格助詞） | B12: 〜と（相手） | C12: いっしょに行う相手を示す。 | D12: ともだちと はなします。
... A97: その他・文法用語 | B97: 連体修飾 | C97: 文で名詞をくわしく説明する。 | D97: これは ははが くれた ゆびわです。

Sheet 文型集計
A1: グループ | B1: 文型数
A2: 助詞（格助詞） | B2: =COUNTIF(N5文型!$A$2:$A$97,A2) -> 16
A3: とりたて・例示・限定 | B3: =COUNTIF(N5文型!$A$2:$A$97,A3) -> 5
A4: 文末表現・ムード | B4: =COUNTIF(N5文型!$A$2:$A$97,A4) -> 9
A5: 存在・所有・授受 | B5: =COUNTIF(N5文型!$A$2:$A$97,A5) -> 7
A6: 好き・きらい・希望 | B6: =COUNTIF(N5文型!$A$2:$A$97,A6) -> 4
A7: 動詞のテ形の文型 | B7: =COUNTIF(N5文型!$A$2:$A$97,A7) -> 11
A8: 許可・禁止・義務・助言 | B8: =COUNTIF(N5文型!$A$2:$A$97,A8) -> 4
A9: 変化・状態 | B9: =COUNTIF(N5文型!$A$2:$A$97,A9) -> 7
A10: 比較・程度・頻度 | B10: =COUNTIF(N5文型!$A$2:$A$97,A10) -> 11
A11: 指示詞・疑問詞 | B11: =COUNTIF(N5文型!$A$2:$A$97,A11) -> 9
A12: 理由・目的 | B12: =COUNTIF(N5文型!$A$2:$A$97,A12) -> 3
A13: い形容詞・活用 | B13: =COUNTIF(N5文型!$A$2:$A$97,A13) -> 3
A14: 感覚・可能の表現 | B14: =COUNTIF(N5文型!$A$2:$A$97,A14) -> 3
A15: その他・文法用語 | B15: =COUNTIF(N5文型!$A$2:$A$97,A15) -> 4
A16: 合計 | B16: =SUM(B2:B15) -> 96

Sheet グループ集計
A1: グループ | B1: 語数
A2: 動詞 | B2: =COUNTIF(語彙グループ別!$A$2:$A$965,A2) -> 126
A3: い形容詞 | B3: =COUNTIF(語彙グループ別!$A$2:$A$965,A3) -> 68
A4: な形容詞 | B4: =COUNTIF(語彙グループ別!$A$2:$A$965,A4) -> 20
A5: 副詞 | B5: =COUNTIF(語彙グループ別!$A$2:$A$965,A5) -> 27
A6: 外来語（カタカナ） | B6: =COUNTIF(語彙グループ別!$A$2:$A$965,A6) -> 58
A7: 時間・暦 | B7: =COUNTIF(語彙グループ別!$A$2:$A$965,A7) -> 77
A8: 家族・人 | B8: =COUNTIF(語彙グループ別!$A$2:$A$965,A8) -> 35
A9: 体 | B9: =COUNTIF(語彙グループ別!$A$2:$A$965,A9) -> 14
A10: 食べ物・飲み物 | B10: =COUNTIF(語彙グループ別!$A$2:$A$965,A10) -> 43
A11: 場所・建物 | B11: =COUNTIF(語彙グループ別!$A$2:$A$965,A11) -> 47
A12: 乗り物 | B12: =COUNTIF(語彙グループ別!$A$2:$A$965,A12) -> 10
A13: 衣服 | B13: =COUNTIF(語彙グループ別!$A$2:$A$965,A13) -> 12
... A31: その他 | B31: =COUNTIF(語彙グループ別!$A$2:$A$965,A31) -> 4
A32: 合計 | B32: =SUM(B2:B31) -> 963
